[{
  "comments": [{
    "author": {
      "login": "cloud-fan"
    },
    "body": "These function APIs will be implemented by users and called by us, why do we declare it to throw exceptions? It brings a lot of trouble when using it in codegen, but seems no benefit?  cc @rxin  \n",
    "commit": "af0d19312fd7dc89aed192a9787f224c9d347180",
    "createdAt": "2016-04-04T06:37:42Z",
    "diffHunk": "@@ -23,5 +23,5 @@\n  * Base interface for a map function used in Dataset's map function.\n  */\n public interface MapFunction<T, U> extends Serializable {\n-  U call(T value) throws Exception;"
  }, {
    "author": {
      "login": "rxin"
    },
    "body": "If they don't, then users must catch all exceptions and can never throw checked exceptions anymore. We shouldn't change this.\n",
    "commit": "af0d19312fd7dc89aed192a9787f224c9d347180",
    "createdAt": "2016-04-04T06:44:52Z",
    "diffHunk": "@@ -23,5 +23,5 @@\n  * Base interface for a map function used in Dataset's map function.\n  */\n public interface MapFunction<T, U> extends Serializable {\n-  U call(T value) throws Exception;"
  }],
  "prId": 12087
}]